Workbook
Name Excel_BuiltIn__FilterDatabase_7: #REF!
Name Excel_BuiltIn__FilterDatabase_7: #REF!
Name Excel_BuiltIn_Print_Area_2: #REF!
Name Excel_BuiltIn_Print_Area_2: #REF!
Name Excel_BuiltIn_Print_Area_47: #REF!
Name Excel_BuiltIn_Print_Area_47: #REF!
Name Excel_BuiltIn_Print_Area_57: #REF!
Name Excel_BuiltIn_Print_Area_57: #REF!
Name Excel_BuiltIn_Print_Area_61: #REF!
Name Excel_BuiltIn_Print_Area_61: #REF!
Name MFO: 'ORS-BURS'!$N$12:$N$18
Name MFO: #REF!
Name nca: #REF!
Name nca: #REF!
Name NEDA: 'ORS-BURS'!$O$3:$O$9
Name NEDA_General_Fund: 'ORS-BURS'!$O$3:$O$9
Name RDC: 'ORS-BURS'!$P$3:$P$4
Name RDC_General_Fund: 'ORS-BURS'!$P$3:$P$9
Name su: '[1]823'!$A$40:$F$46
Name Trust: 'ORS-BURS'!$Q$3
Name Trust_Fund: 'ORS-BURS'!$Q$3:$Q$9
Name UACS: 'ORS-BURS'!$N$21:$N$22
Name UACS: #REF!

Sheet TOI
A1: ='ORS-BURS'!A3:I3 -> REGIONAL DEVELOPMENT COUNCIL 5
A2: ='ORS-BURS'!A4:I4 -> Arimbay Legazpi City
G4: Local Travel Order No. _________________
A6: NAME: | B6: Ronaldo B. Bañas | F6: POSITION: | G6: Information Systems Analyst II
A7: DESTINATION: | C7: Province of Sorsogon | F7: STATION: | G7: DEPDev Region 5
A8: TRAVEL PERIOD: | C8: September 22 to 26, 2025 | F8: PURPOSE: | G8: Field verification of flood control projects in the Province of Sorsogon
A9: Per approved Itinerary of Travel, actual expenses for meals, gasoline, toll fees, per diems and miscellaneous expenses are hereby authorized chargeable against the allocation for travel expenditures, subject to availability of funds and the usual accounting and auditing rules and regulations.
A10: ITINERARY OF TRAVEL
A11: DATE | B11: PLACE | D11: TIME | F11: Transportation Means | G11: TRAVEL EXPENSES
D12: ETD | E12: ETA | G12: Transportation | H12: Lodging | I12: Meals | J12: Incidental Expenses | K12: Total
A13: 09/22/2025 | B13: Official Station to Sorsogon City | D13: 0.29166667 | E13: 0.35416667 | F13: DEPDev Vehicle | I13: 450 | J13: 300 | K13: =SUM(G13:J13) -> 750
B14: Sorsogon City to Official Station | D14: 0.75 | E14: 0.8125 | K14: =SUM(G14:J14) -> 0
A15: 09/23/2025 | B15: Official Station to Sorsogon City | D15: 0.29166667 | E15: 0.35416667 | F15: DEPDev Vehicle | I15: 450 | J15: 300 | K15: =SUM(G15:J15) -> 750
B16: Sorsogon City to Official Station | D16: 0.75 | E16: 0.8125
A17: 09/24/2025 | B17: Official Station to Sorsogon City | D17: 0.29166667 | E17: 0.35416667 | F17: DEPDev Vehicle | I17: 450 | J17: 300 | K17: =SUM(G17:J17) -> 750
B18: Sorsogon City to Official Station | D18: 0.75 | E18: 0.8125
A19: 09/25/2025 | B19: Official Station to Sorsogon City | D19: 0.29166667 | E19: 0.35416667 | F19: DEPDev Vehicle | I19: 450 | J19: 300 | K19: =SUM(G19:J19) -> 750
B20: Sorsogon City to Official Station | D20: 0.75 | E20: 0.8125
A21: 09/26/2025 | B21: Official Station to Sorsogon City | D21: 0.29166667 | E21: 0.35416667 | F21: DEPDev Vehicle | I21: 450 | J21: 300 | K21: =SUM(G21:J21) -> 750
B22: Sorsogon City to Official Station | D22: 0.75 | E22: 0.8125 | K22: =SUM(G22:J22) -> 0
A23: TOTAL P | K23: =SUM(K13:K22) -> 3750
A24: Requesting for cash advance: | F24: ORS/BURS No.
A25: Upon completion of travel, the usual certificate of appearance and certificate of travel completed shall be submitted to the Administrative Staff and report thereon shall be submitted within fifteen (15) days from completion of said travel, otherwise, the amount corresponding to said cash advances shall be deducted from the next succeeding payday.
A26: PREPARED BY: _______ Position | F26: REVIEWED/RECOMMENDING APPROVAL: I certify that: (1) I reviewed the foregoing itinerary, (2) the travel is necessary to the service, (3) the period covered is reasonable, (4) the expenses claimed are proper.
A28: RONALDO B. BAÑAS
A29: =G6 -> Information Systems Analyst II
A30: DATE PREPARED: | C30: September 17,2025 | F30: GWENDOLYN S. BITARE
A31: ORS No. | F31: Chief AO, FAD
A32: APPROVED:
A33: JASMIN C. ZANTUA
A34: OIC Assistant Regional Director

Sheet ORS-BURS
M1: THESE COLUMNS ARE LINKED WITH THE TEMPLATE. PLEASE DO NOT MAKE ANY CHANGES. THANK YOU.
A2: =IF(A10="Trust","BUDGET UTILIZATION REQUEST AND STATUS ","OBLIGATION REQUEST AND STATUS") -> OBLIGATION REQUEST AND STATUS | J2: Serial No. : | O2: NEDA | P2: RDC | Q2: Trust | U2: Date | V2: Payee | W2: Responsibility Center | X2: Particulars | Y2: MFO/PAP | Z2: UACS Object Code | AA2: Amount | AC2: PETTY CASH VOUCHER | AH2: No. : ___________________
A3: =IF(A10="RDC","REGIONAL DEVELOPMENT COUNCIL 5","NATIONAL ECONOMIC AND DEVELOPMENT AUTHORITY 5") -> REGIONAL DEVELOPMENT COUNCIL 5 | J3: Date : | K3: =TOI!C30 -> September 17,2025 | M3: NEDA | N3: NEDA General Fund | O3: GAS 100000100001000 | P3: RDC 310100100003000 | Q3: GAS 100000100001000 | U3: =K3 -> September 17,2025 | V3: =D5 -> Ronaldo B. Bañas | W3: =A10 -> RDC | X3: =D10 -> Travel allowance for the following purpose: | Y3: =I10 -> RDC 310100100003000 | Z3: =J10 -> Traveling Expenses-local 50201010 00 | AA3: =K10 -> 3750
A4: Arimbay Legazpi City | J4: Fund Cluster : | K4: 01 RAF | L4: MOOE | M4: RDC | N4: RDC General Fund | O4: PFPD 310100100001000 | P4: RPMES 310300100001000 | Y4: =I11 -> 0 | Z4: =J11 -> 0 | AA4: =K11 -> 0 | AC4: Entity Name : | AD4: =#REF! -> #REF! | AH4: Date : | AI4: =K3 -> September 17,2025
A5: Payee | D5: =TOI!B6 -> Ronaldo B. Bañas | M5: Trust | N5: Trust Fund | O5: TSSS IAC 310100100002000 | Y5: =I12 -> 0 | Z5: =J12 -> 0 | AA5: =K12 -> 0 | AC5: Fund Cluster: | AD5: =CONCATENATE(K4," ",L4) -> 01 RAF MOOE
A6: Office | D6: =TOI!G7 -> DEPDev Region 5 | O6: SS RDC 310100100003000 | Y6: =I13 -> 0 | Z6: =J13 -> 0 | AA6: =K13 -> 0
A7: Address | D7: Arimbay, Legazpi City | O7: DRD 310100100004000 | Y7: =I14 -> 0 | Z7: =J14 -> 0 | AA7: =K14 -> 0 | AC7: Payee/Office : | AD7: =D5 -> Ronaldo B. Bañas | AH7: Responsibility Center Code:
A8: Responsibility Center | D8: Particulars | I8: MFO/PAP | J8: UACS Object Code | K8: Amount | O8: PDIBPD 310200100002000 | Y8: =I15 -> 0 | Z8: =J15 -> 0 | AA8: =K15 -> 0 | AC8: Address : | AD8: =D7 -> Arimbay, Legazpi City | AH8: =I10 -> RDC 310100100003000
N9: Catering services during the | O9: PMED 310300100001000 | Y9: =I16 -> 0 | Z9: =J16 -> 0 | AA9: =K16 -> 0
A10: RDC | D10: Travel allowance for the following purpose: | I10: RDC 310100100003000 | J10: Traveling Expenses-local 50201010 00 | K10: =TOI!K23 -> 3750 | Y10: =I17 -> 0 | Z10: =J17 -> 0 | AA10: =K17 -> 0
A11: =IF(A10="Trust","Fund","General Fund") -> General Fund | N11: MFO | O11: FALSE | P11: =IF(#REF!="Standard",#REF!*250," ") -> #REF! | Q11: =IF(#REF!="Per Contract",#REF!*235," ") -> #REF! | R11: =SUM(P11:Q11) -> #REF! | Y11: =I18 -> 0 | Z11: =J18 -> 0 | AA11: =K18 -> 0 | AC11: I. To be filled out upon request | AG11: II. To be filled out upon liquidation
D12: =TOI!G8 -> Field verification of flood control projects in the Province of Sorsogon | N12: GAS 100000100001000 | O12: TRUE | P12: =IF(#REF!="Standard",#REF!*150," ") -> #REF! | Q12: =IF(#REF!="Per Contract",#REF!*125," ") -> #REF! | R12: =SUM(P12:Q12) -> #REF! | Y12: =I19 -> 0 | Z12: =J19 -> 0 | AA12: =K19 -> 0
N13: PFPD 310100100001000 | O13: FALSE | P13: =IF(#REF!="Standard",#REF!*250," ") -> #REF! | Q13: =IF(#REF!="Per Contract",#REF!*235," ") -> #REF! | R13: =SUM(P13:Q13) -> #REF! | Y13: =I20 -> 0 | Z13: =J20 -> 0 | AA13: =K20 -> 0 | AC13: Particulars | AE13: Amount
N14: TSSS IAC 310100100002000 | O14: FALSE | P14: =IF(#REF!="Standard",#REF!*150," ") -> #REF! | Q14: =IF(#REF!="Per Contract",#REF!*125," ") -> #REF! | R14: =SUM(P14:Q14) -> #REF! | Y14: =I21 -> 0 | Z14: =J21 -> 0 | AA14: =K21 -> 3750 | AC14: =D10 -> Travel allowance for the following purpose: | AE14: =K21 -> 3750 | AG14: Total Amount Granted | AI14: =AE15 -> 0
N15: SS RDC 310100100003000 | O15: FALSE | P15: =IF(#REF!="Standard",#REF!*250," ") -> #REF! | Q15: =IF(#REF!="Per Contract",#REF!*235," ") -> #REF! | R15: =SUM(P15:Q15) -> #REF!
N16: DRD 310100100004000 | O16: FALSE | P16: =IF(#REF!="Standard",#REF!*150," ") -> #REF! | Q16: =IF(#REF!="Per Contract",#REF!*125," ") -> #REF! | R16: =SUM(P16:Q16) -> #REF! | AA16: This box is for FAD use. Please do not make any changes. Thank you. | AG16: Total Amount Paid per
N17: PDIBPD 310200100002000 | AG17: OR/Invoice No.
N18: PMED 310300100001000
AG19: Amount Refunded/ (Reimbursed)
N20: UACS Code
K21: =SUM(K10:L20) -> 3750 | N21: =CONCATENATE(O21," ",R21) -> Traveling Expenses-local 50201010 00 | O21: Traveling Expenses-local | R21: 50201010 00 | AC21: Requested by:
A22: A. | D22: Charges to appropriation/allotment are | I22: B. | N22: =CONCATENATE(O22," ",R22) -> Training Expenses 50202010 00 | O22: Training Expenses | R22: 50202010 00 | AH22: Received Refund
B23: Certified:
B24: necessary, lawful and under my direct supervision;and | I24: Certified: Allotment available and obligated for the | AC24: =AD7 -> Ronaldo B. Bañas | AH24: Reimbursement Paid
B25: supporting documents valid, proper and legal | I25: purpose/adjustment necessary as indicated above | AC25: Name of Requestor
AC26: Signature over Printed Name
A27: Signature : | I27: Signature :
A28: Printed Name: | C28: =TOI!F30 -> GWENDOLYN S. BITARE | I28: Printed Name: | J28: MARINEE OBING | AC28: Approved by:
A29: Position: | C29: =TOI!F31 -> Chief AO, FAD | I29: Position : | J29: OIC Head, Budget Division/Unit/Authorized Representative | AG29: =AC36 -> GWENDOLYN S. BITARE
A30: Date: | C30: =K3 -> September 17,2025 | I30: Date : | AG30: Signature over Printed Name
AC31: AGNES E. TOLENTINO | AG31: Petty Cash Custodian
A32: C. | B32: STATUS OF OBLIGATION | AC32: Signature over Printed Name
A33: Reference | H33: Amount | AC33: Name of Immediate Supervisor
A34: Date | B34: Particulars | E34: ORS/JEV/Check/ ADA/TRA No. | H34: Obligation | I34: Payable | J34: Payment | K34: Balance
K35: Not Yet Due | L35: Due and Demandable | AC35: Paid by: | AH35: Liquidation Submitted
H36: (a) | I36: (b) | J36: (c) | K36: (a-b) | L36: (b-c) | AC36: GWENDOLYN S. BITARE | AH36: Reimbursement Received by:
A37: =+K3 -> September 17,2025 | B37: =CONCATENATE(D10,D12) -> Travel allowance for the following purpose:Field verification of flood control projects in the Province of Sorsogon | H37: =+K21 -> 3750 | K37: =+H37 -> 3750 | AC37: Signature over Printed Name
AC40: Cash Received by: | AG40: __________________________
AC43: =AD7 -> Ronaldo B. Bañas | AG43: Signature over Printed Name
AC44: Payee | AG44: Payee
...

Sheet Rates
F1: ANNEX A
A4: GUIDE IN COMPUTING DAILY ALLOWANCE FOR LOCAL TRAVELS BEYOND 50-KM RADIUS
A6: Destination | B6: Maximum Allowance | C6: Lodging (50%) | D6: Per Diem (30% or 10% per meal) | F6: Incidental (20%)
D7: Per Diem | E7: Per Meal
A8: Regions 1, 2 3, 5, 8, 9, 12, 13, ARMM | B8: 1500 | C8: =B8*0.5 -> 750 | D8: =B8*0.3 -> 450 | E8: =D8/3 -> 150 | F8: =B8*0.2 -> 300
A9: Regions 6, 7, 10, 11, CAR | B9: 1800 | C9: =B9*0.5 -> 900 | D9: =B9*0.3 -> 540 | E9: =D9/3 -> 180 | F9: =B9*0.2 -> 360
A10: Regions 4-A, 4-B, NCR | B10: 2200 | C10: =B10*0.5 -> 1100 | D10: =B10*0.3 -> 660 | E10: =D10/3 -> 220 | F10: =B10*0.2 -> 440
A13: The allowance shall be apportioned as follows:
A14: 100% : Day of arrival at point of destination (regardless of time) and succeeding days thereof on official business (50% lodgin/accommodation; 30% meals; 20% incidental expenses)
A15: 50% : Day of departure for permanent official station (regardless of time) if other than date of arrival (30% meals; 20% incidental expenses)
A16: Note: The corresponding allowance for any meals provided by the government during the official travel shall not be deducted from the travel claim.
